2025-03-30 17:02:21,996 - DEBUG - Using selector: EpollSelector
2025-03-30 17:10:39,724 - ERROR - an error occurred during closing of asynchronous generator <async_generator object stdio_client at 0x7d7927a86840>
asyncgen: <async_generator object stdio_client at 0x7d7927a86840>
  + Exception Group Traceback (most recent call last):
  |   File "/home/biniam/Desktop/Projects/mcp-xp/venv/lib/python3.10/site-packages/anyio/_backends/_asyncio.py", line 772, in __aexit__
  |     raise BaseExceptionGroup(
  | exceptiongroup.ExceptionGroup: unhandled errors in a TaskGroup (1 sub-exception)
  +-+---------------- 1 ----------------
    | Traceback (most recent call last):
    |   File "/home/biniam/Desktop/Projects/mcp-xp/venv/lib/python3.10/site-packages/mcp/client/stdio/__init__.py", line 173, in stdio_client
    |     yield read_stream, write_stream
    | GeneratorExit
    | 
    | During handling of the above exception, another exception occurred:
    | 
    | Traceback (most recent call last):
    |   File "/home/biniam/Desktop/Projects/mcp-xp/venv/lib/python3.10/site-packages/mcp/client/stdio/__init__.py", line 179, in stdio_client
    |     process.terminate()
    |   File "/home/biniam/Desktop/Projects/mcp-xp/venv/lib/python3.10/site-packages/anyio/_backends/_asyncio.py", line 1085, in terminate
    |     self._process.terminate()
    |   File "/usr/lib/python3.10/asyncio/subprocess.py", line 140, in terminate
    |     self._transport.terminate()
    |   File "/usr/lib/python3.10/asyncio/base_subprocess.py", line 149, in terminate
    |     self._check_proc()
    |   File "/usr/lib/python3.10/asyncio/base_subprocess.py", line 142, in _check_proc
    |     raise ProcessLookupError()
    | ProcessLookupError
    +------------------------------------

During handling of the above exception, another exception occurred:

Traceback (most recent call last):
  File "/home/biniam/Desktop/Projects/mcp-xp/venv/lib/python3.10/site-packages/mcp/client/stdio/__init__.py", line 166, in stdio_client
    async with (
  File "/home/biniam/Desktop/Projects/mcp-xp/venv/lib/python3.10/site-packages/anyio/_backends/_asyncio.py", line 778, in __aexit__
    if self.cancel_scope.__exit__(type(exc), exc, exc.__traceback__):
  File "/home/biniam/Desktop/Projects/mcp-xp/venv/lib/python3.10/site-packages/anyio/_backends/_asyncio.py", line 457, in __exit__
    raise RuntimeError(
RuntimeError: Attempted to exit cancel scope in a different task than it was entered in
2025-03-30 17:10:39,726 - ERROR - an error occurred during closing of asynchronous generator <async_generator object stdio_client at 0x7d7927a85840>
asyncgen: <async_generator object stdio_client at 0x7d7927a85840>
  + Exception Group Traceback (most recent call last):
  |   File "/home/biniam/Desktop/Projects/mcp-xp/venv/lib/python3.10/site-packages/anyio/_backends/_asyncio.py", line 772, in __aexit__
  |     raise BaseExceptionGroup(
  | exceptiongroup.BaseExceptionGroup: unhandled errors in a TaskGroup (1 sub-exception)
  +-+---------------- 1 ----------------
    | Traceback (most recent call last):
    |   File "/home/biniam/Desktop/Projects/mcp-xp/venv/lib/python3.10/site-packages/mcp/client/stdio/__init__.py", line 173, in stdio_client
    |     yield read_stream, write_stream
    | GeneratorExit
    +------------------------------------

During handling of the above exception, another exception occurred:

Traceback (most recent call last):
  File "/home/biniam/Desktop/Projects/mcp-xp/venv/lib/python3.10/site-packages/mcp/client/stdio/__init__.py", line 166, in stdio_client
    async with (
  File "/home/biniam/Desktop/Projects/mcp-xp/venv/lib/python3.10/site-packages/anyio/_backends/_asyncio.py", line 778, in __aexit__
    if self.cancel_scope.__exit__(type(exc), exc, exc.__traceback__):
  File "/home/biniam/Desktop/Projects/mcp-xp/venv/lib/python3.10/site-packages/anyio/_backends/_asyncio.py", line 457, in __exit__
    raise RuntimeError(
RuntimeError: Attempted to exit cancel scope in a different task than it was entered in
2025-03-30 17:10:39,726 - ERROR - an error occurred during closing of asynchronous generator <async_generator object stdio_client at 0x7d7927a86f40>
asyncgen: <async_generator object stdio_client at 0x7d7927a86f40>
  + Exception Group Traceback (most recent call last):
  |   File "/home/biniam/Desktop/Projects/mcp-xp/venv/lib/python3.10/site-packages/anyio/_backends/_asyncio.py", line 772, in __aexit__
  |     raise BaseExceptionGroup(
  | exceptiongroup.BaseExceptionGroup: unhandled errors in a TaskGroup (1 sub-exception)
  +-+---------------- 1 ----------------
    | Traceback (most recent call last):
    |   File "/home/biniam/Desktop/Projects/mcp-xp/venv/lib/python3.10/site-packages/mcp/client/stdio/__init__.py", line 173, in stdio_client
    |     yield read_stream, write_stream
    | GeneratorExit
    +------------------------------------

During handling of the above exception, another exception occurred:

Traceback (most recent call last):
  File "/home/biniam/Desktop/Projects/mcp-xp/venv/lib/python3.10/site-packages/mcp/client/stdio/__init__.py", line 166, in stdio_client
    async with (
  File "/home/biniam/Desktop/Projects/mcp-xp/venv/lib/python3.10/site-packages/anyio/_backends/_asyncio.py", line 778, in __aexit__
    if self.cancel_scope.__exit__(type(exc), exc, exc.__traceback__):
  File "/home/biniam/Desktop/Projects/mcp-xp/venv/lib/python3.10/site-packages/anyio/_backends/_asyncio.py", line 457, in __exit__
    raise RuntimeError(
RuntimeError: Attempted to exit cancel scope in a different task than it was entered in
2025-03-30 17:10:41,539 - DEBUG - Using selector: EpollSelector
2025-03-30 17:10:41,540 - INFO - Starting chat session...
2025-03-30 17:10:41,919 - INFO - Server sqlite initialized successfully.
2025-03-30 17:10:44,017 - INFO - Server puppeteer initialized successfully.
2025-03-30 17:12:20,362 - ERROR - an error occurred during closing of asynchronous generator <async_generator object stdio_client at 0x71788468a740>
asyncgen: <async_generator object stdio_client at 0x71788468a740>
  + Exception Group Traceback (most recent call last):
  |   File "/home/biniam/Desktop/Projects/mcp-xp/venv/lib/python3.10/site-packages/anyio/_backends/_asyncio.py", line 772, in __aexit__
  |     raise BaseExceptionGroup(
  | exceptiongroup.ExceptionGroup: unhandled errors in a TaskGroup (1 sub-exception)
  +-+---------------- 1 ----------------
    | Traceback (most recent call last):
    |   File "/home/biniam/Desktop/Projects/mcp-xp/venv/lib/python3.10/site-packages/mcp/client/stdio/__init__.py", line 173, in stdio_client
    |     yield read_stream, write_stream
    | GeneratorExit
    | 
    | During handling of the above exception, another exception occurred:
    | 
    | Traceback (most recent call last):
    |   File "/home/biniam/Desktop/Projects/mcp-xp/venv/lib/python3.10/site-packages/mcp/client/stdio/__init__.py", line 179, in stdio_client
    |     process.terminate()
    |   File "/home/biniam/Desktop/Projects/mcp-xp/venv/lib/python3.10/site-packages/anyio/_backends/_asyncio.py", line 1085, in terminate
    |     self._process.terminate()
    |   File "/usr/lib/python3.10/asyncio/subprocess.py", line 140, in terminate
    |     self._transport.terminate()
    |   File "/usr/lib/python3.10/asyncio/base_subprocess.py", line 149, in terminate
    |     self._check_proc()
    |   File "/usr/lib/python3.10/asyncio/base_subprocess.py", line 142, in _check_proc
    |     raise ProcessLookupError()
    | ProcessLookupError
    +------------------------------------

During handling of the above exception, another exception occurred:

Traceback (most recent call last):
  File "/home/biniam/Desktop/Projects/mcp-xp/venv/lib/python3.10/site-packages/mcp/client/stdio/__init__.py", line 166, in stdio_client
    async with (
  File "/home/biniam/Desktop/Projects/mcp-xp/venv/lib/python3.10/site-packages/anyio/_backends/_asyncio.py", line 778, in __aexit__
    if self.cancel_scope.__exit__(type(exc), exc, exc.__traceback__):
  File "/home/biniam/Desktop/Projects/mcp-xp/venv/lib/python3.10/site-packages/anyio/_backends/_asyncio.py", line 457, in __exit__
    raise RuntimeError(
RuntimeError: Attempted to exit cancel scope in a different task than it was entered in
2025-03-30 17:12:20,366 - ERROR - an error occurred during closing of asynchronous generator <async_generator object stdio_client at 0x717884689740>
asyncgen: <async_generator object stdio_client at 0x717884689740>
  + Exception Group Traceback (most recent call last):
  |   File "/home/biniam/Desktop/Projects/mcp-xp/venv/lib/python3.10/site-packages/anyio/_backends/_asyncio.py", line 772, in __aexit__
  |     raise BaseExceptionGroup(
  | exceptiongroup.BaseExceptionGroup: unhandled errors in a TaskGroup (1 sub-exception)
  +-+---------------- 1 ----------------
    | Traceback (most recent call last):
    |   File "/home/biniam/Desktop/Projects/mcp-xp/venv/lib/python3.10/site-packages/mcp/client/stdio/__init__.py", line 173, in stdio_client
    |     yield read_stream, write_stream
    | GeneratorExit
    +------------------------------------

During handling of the above exception, another exception occurred:

Traceback (most recent call last):
  File "/home/biniam/Desktop/Projects/mcp-xp/venv/lib/python3.10/site-packages/mcp/client/stdio/__init__.py", line 166, in stdio_client
    async with (
  File "/home/biniam/Desktop/Projects/mcp-xp/venv/lib/python3.10/site-packages/anyio/_backends/_asyncio.py", line 778, in __aexit__
    if self.cancel_scope.__exit__(type(exc), exc, exc.__traceback__):
  File "/home/biniam/Desktop/Projects/mcp-xp/venv/lib/python3.10/site-packages/anyio/_backends/_asyncio.py", line 457, in __exit__
    raise RuntimeError(
RuntimeError: Attempted to exit cancel scope in a different task than it was entered in
2025-03-30 17:12:20,368 - ERROR - an error occurred during closing of asynchronous generator <async_generator object stdio_client at 0x71788468ae40>
asyncgen: <async_generator object stdio_client at 0x71788468ae40>
  + Exception Group Traceback (most recent call last):
  |   File "/home/biniam/Desktop/Projects/mcp-xp/venv/lib/python3.10/site-packages/anyio/_backends/_asyncio.py", line 772, in __aexit__
  |     raise BaseExceptionGroup(
  | exceptiongroup.BaseExceptionGroup: unhandled errors in a TaskGroup (1 sub-exception)
  +-+---------------- 1 ----------------
    | Traceback (most recent call last):
    |   File "/home/biniam/Desktop/Projects/mcp-xp/venv/lib/python3.10/site-packages/mcp/client/stdio/__init__.py", line 173, in stdio_client
    |     yield read_stream, write_stream
    | GeneratorExit
    +------------------------------------

During handling of the above exception, another exception occurred:

Traceback (most recent call last):
  File "/home/biniam/Desktop/Projects/mcp-xp/venv/lib/python3.10/site-packages/mcp/client/stdio/__init__.py", line 166, in stdio_client
    async with (
  File "/home/biniam/Desktop/Projects/mcp-xp/venv/lib/python3.10/site-packages/anyio/_backends/_asyncio.py", line 778, in __aexit__
    if self.cancel_scope.__exit__(type(exc), exc, exc.__traceback__):
  File "/home/biniam/Desktop/Projects/mcp-xp/venv/lib/python3.10/site-packages/anyio/_backends/_asyncio.py", line 457, in __exit__
    raise RuntimeError(
RuntimeError: Attempted to exit cancel scope in a different task than it was entered in
2025-03-30 17:14:34,785 - DEBUG - Using selector: EpollSelector
2025-03-30 17:14:34,786 - INFO - Starting chat session...
2025-03-30 17:14:35,911 - INFO - Server sqlite initialized successfully.
2025-03-30 17:14:37,455 - INFO - Server puppeteer initialized successfully.
2025-03-30 17:19:07,322 - ERROR - Error during cleanup of server sqlite: Attempted to exit cancel scope in a different task than it was entered in
2025-03-30 17:19:07,349 - ERROR - an error occurred during closing of asynchronous generator <async_generator object stdio_client at 0x7d5170981640>
asyncgen: <async_generator object stdio_client at 0x7d5170981640>
  + Exception Group Traceback (most recent call last):
  |   File "/home/biniam/Desktop/Projects/mcp-xp/venv/lib/python3.10/site-packages/anyio/_backends/_asyncio.py", line 772, in __aexit__
  |     raise BaseExceptionGroup(
  | exceptiongroup.ExceptionGroup: unhandled errors in a TaskGroup (1 sub-exception)
  +-+---------------- 1 ----------------
    | Traceback (most recent call last):
    |   File "/home/biniam/Desktop/Projects/mcp-xp/venv/lib/python3.10/site-packages/mcp/client/stdio/__init__.py", line 173, in stdio_client
    |     yield read_stream, write_stream
    | GeneratorExit
    | 
    | During handling of the above exception, another exception occurred:
    | 
    | Traceback (most recent call last):
    |   File "/home/biniam/Desktop/Projects/mcp-xp/venv/lib/python3.10/site-packages/mcp/client/stdio/__init__.py", line 179, in stdio_client
    |     process.terminate()
    |   File "/home/biniam/Desktop/Projects/mcp-xp/venv/lib/python3.10/site-packages/anyio/_backends/_asyncio.py", line 1085, in terminate
    |     self._process.terminate()
    |   File "/usr/lib/python3.10/asyncio/subprocess.py", line 140, in terminate
    |     self._transport.terminate()
    |   File "/usr/lib/python3.10/asyncio/base_subprocess.py", line 149, in terminate
    |     self._check_proc()
    |   File "/usr/lib/python3.10/asyncio/base_subprocess.py", line 142, in _check_proc
    |     raise ProcessLookupError()
    | ProcessLookupError
    +------------------------------------

During handling of the above exception, another exception occurred:

Traceback (most recent call last):
  File "/home/biniam/Desktop/Projects/mcp-xp/venv/lib/python3.10/site-packages/mcp/client/stdio/__init__.py", line 166, in stdio_client
    async with (
  File "/home/biniam/Desktop/Projects/mcp-xp/venv/lib/python3.10/site-packages/anyio/_backends/_asyncio.py", line 778, in __aexit__
    if self.cancel_scope.__exit__(type(exc), exc, exc.__traceback__):
  File "/home/biniam/Desktop/Projects/mcp-xp/venv/lib/python3.10/site-packages/anyio/_backends/_asyncio.py", line 457, in __exit__
    raise RuntimeError(
RuntimeError: Attempted to exit cancel scope in a different task than it was entered in
2025-03-30 17:19:07,352 - ERROR - an error occurred during closing of asynchronous generator <async_generator object stdio_client at 0x7d5170982e40>
asyncgen: <async_generator object stdio_client at 0x7d5170982e40>
  + Exception Group Traceback (most recent call last):
  |   File "/home/biniam/Desktop/Projects/mcp-xp/venv/lib/python3.10/site-packages/anyio/_backends/_asyncio.py", line 772, in __aexit__
  |     raise BaseExceptionGroup(
  | exceptiongroup.BaseExceptionGroup: unhandled errors in a TaskGroup (1 sub-exception)
  +-+---------------- 1 ----------------
    | Traceback (most recent call last):
    |   File "/home/biniam/Desktop/Projects/mcp-xp/venv/lib/python3.10/site-packages/mcp/client/stdio/__init__.py", line 173, in stdio_client
    |     yield read_stream, write_stream
    | GeneratorExit
    +------------------------------------

During handling of the above exception, another exception occurred:

Traceback (most recent call last):
  File "/home/biniam/Desktop/Projects/mcp-xp/venv/lib/python3.10/site-packages/mcp/client/stdio/__init__.py", line 166, in stdio_client
    async with (
  File "/home/biniam/Desktop/Projects/mcp-xp/venv/lib/python3.10/site-packages/anyio/_backends/_asyncio.py", line 778, in __aexit__
    if self.cancel_scope.__exit__(type(exc), exc, exc.__traceback__):
  File "/home/biniam/Desktop/Projects/mcp-xp/venv/lib/python3.10/site-packages/anyio/_backends/_asyncio.py", line 457, in __exit__
    raise RuntimeError(
RuntimeError: Attempted to exit cancel scope in a different task than it was entered in
2025-03-30 17:19:09,064 - DEBUG - Using selector: EpollSelector
2025-03-30 17:19:09,065 - INFO - Starting chat session...
2025-03-30 17:19:09,432 - INFO - Server sqlite initialized successfully.
2025-03-30 17:19:11,220 - INFO - Server puppeteer initialized successfully.
2025-03-30 17:24:28,797 - ERROR - Error during cleanup of server sqlite: Attempted to exit cancel scope in a different task than it was entered in
2025-03-30 17:24:28,823 - ERROR - an error occurred during closing of asynchronous generator <async_generator object stdio_client at 0x7543faf95640>
asyncgen: <async_generator object stdio_client at 0x7543faf95640>
  + Exception Group Traceback (most recent call last):
  |   File "/home/biniam/Desktop/Projects/mcp-xp/venv/lib/python3.10/site-packages/anyio/_backends/_asyncio.py", line 772, in __aexit__
  |     raise BaseExceptionGroup(
  | exceptiongroup.ExceptionGroup: unhandled errors in a TaskGroup (1 sub-exception)
  +-+---------------- 1 ----------------
    | Traceback (most recent call last):
    |   File "/home/biniam/Desktop/Projects/mcp-xp/venv/lib/python3.10/site-packages/mcp/client/stdio/__init__.py", line 173, in stdio_client
    |     yield read_stream, write_stream
    | GeneratorExit
    | 
    | During handling of the above exception, another exception occurred:
    | 
    | Traceback (most recent call last):
    |   File "/home/biniam/Desktop/Projects/mcp-xp/venv/lib/python3.10/site-packages/mcp/client/stdio/__init__.py", line 179, in stdio_client
    |     process.terminate()
    |   File "/home/biniam/Desktop/Projects/mcp-xp/venv/lib/python3.10/site-packages/anyio/_backends/_asyncio.py", line 1085, in terminate
    |     self._process.terminate()
    |   File "/usr/lib/python3.10/asyncio/subprocess.py", line 140, in terminate
    |     self._transport.terminate()
    |   File "/usr/lib/python3.10/asyncio/base_subprocess.py", line 149, in terminate
    |     self._check_proc()
    |   File "/usr/lib/python3.10/asyncio/base_subprocess.py", line 142, in _check_proc
    |     raise ProcessLookupError()
    | ProcessLookupError
    +------------------------------------

During handling of the above exception, another exception occurred:

Traceback (most recent call last):
  File "/home/biniam/Desktop/Projects/mcp-xp/venv/lib/python3.10/site-packages/mcp/client/stdio/__init__.py", line 166, in stdio_client
    async with (
  File "/home/biniam/Desktop/Projects/mcp-xp/venv/lib/python3.10/site-packages/anyio/_backends/_asyncio.py", line 778, in __aexit__
    if self.cancel_scope.__exit__(type(exc), exc, exc.__traceback__):
  File "/home/biniam/Desktop/Projects/mcp-xp/venv/lib/python3.10/site-packages/anyio/_backends/_asyncio.py", line 457, in __exit__
    raise RuntimeError(
RuntimeError: Attempted to exit cancel scope in a different task than it was entered in
2025-03-30 17:24:28,826 - ERROR - an error occurred during closing of asynchronous generator <async_generator object stdio_client at 0x7543faf96e40>
asyncgen: <async_generator object stdio_client at 0x7543faf96e40>
  + Exception Group Traceback (most recent call last):
  |   File "/home/biniam/Desktop/Projects/mcp-xp/venv/lib/python3.10/site-packages/anyio/_backends/_asyncio.py", line 772, in __aexit__
  |     raise BaseExceptionGroup(
  | exceptiongroup.BaseExceptionGroup: unhandled errors in a TaskGroup (1 sub-exception)
  +-+---------------- 1 ----------------
    | Traceback (most recent call last):
    |   File "/home/biniam/Desktop/Projects/mcp-xp/venv/lib/python3.10/site-packages/mcp/client/stdio/__init__.py", line 173, in stdio_client
    |     yield read_stream, write_stream
    | GeneratorExit
    +------------------------------------

During handling of the above exception, another exception occurred:

Traceback (most recent call last):
  File "/home/biniam/Desktop/Projects/mcp-xp/venv/lib/python3.10/site-packages/mcp/client/stdio/__init__.py", line 166, in stdio_client
    async with (
  File "/home/biniam/Desktop/Projects/mcp-xp/venv/lib/python3.10/site-packages/anyio/_backends/_asyncio.py", line 778, in __aexit__
    if self.cancel_scope.__exit__(type(exc), exc, exc.__traceback__):
  File "/home/biniam/Desktop/Projects/mcp-xp/venv/lib/python3.10/site-packages/anyio/_backends/_asyncio.py", line 457, in __exit__
    raise RuntimeError(
RuntimeError: Attempted to exit cancel scope in a different task than it was entered in
2025-03-30 17:40:11,095 - DEBUG - Using selector: EpollSelector
2025-03-30 17:40:11,096 - INFO - Starting chat session...
2025-03-30 17:40:12,537 - INFO - Server sqlite initialized successfully.
2025-03-30 17:40:14,496 - INFO - Server puppeteer initialized successfully.
2025-03-30 17:40:21,751 - ERROR - Error during cleanup of server sqlite: Attempted to exit cancel scope in a different task than it was entered in
2025-03-30 17:40:21,781 - ERROR - an error occurred during closing of asynchronous generator <async_generator object stdio_client at 0x747dd9b8ee40>
asyncgen: <async_generator object stdio_client at 0x747dd9b8ee40>
  + Exception Group Traceback (most recent call last):
  |   File "/home/biniam/Desktop/Projects/mcp-xp/venv/lib/python3.10/site-packages/anyio/_backends/_asyncio.py", line 772, in __aexit__
  |     raise BaseExceptionGroup(
  | exceptiongroup.BaseExceptionGroup: unhandled errors in a TaskGroup (1 sub-exception)
  +-+---------------- 1 ----------------
    | Traceback (most recent call last):
    |   File "/home/biniam/Desktop/Projects/mcp-xp/venv/lib/python3.10/site-packages/mcp/client/stdio/__init__.py", line 173, in stdio_client
    |     yield read_stream, write_stream
    | GeneratorExit
    +------------------------------------

During handling of the above exception, another exception occurred:

Traceback (most recent call last):
  File "/home/biniam/Desktop/Projects/mcp-xp/venv/lib/python3.10/site-packages/mcp/client/stdio/__init__.py", line 166, in stdio_client
    async with (
  File "/home/biniam/Desktop/Projects/mcp-xp/venv/lib/python3.10/site-packages/anyio/_backends/_asyncio.py", line 778, in __aexit__
    if self.cancel_scope.__exit__(type(exc), exc, exc.__traceback__):
  File "/home/biniam/Desktop/Projects/mcp-xp/venv/lib/python3.10/site-packages/anyio/_backends/_asyncio.py", line 457, in __exit__
    raise RuntimeError(
RuntimeError: Attempted to exit cancel scope in a different task than it was entered in
2025-03-30 17:40:21,782 - ERROR - an error occurred during closing of asynchronous generator <async_generator object stdio_client at 0x747dd9b8d640>
asyncgen: <async_generator object stdio_client at 0x747dd9b8d640>
  + Exception Group Traceback (most recent call last):
  |   File "/home/biniam/Desktop/Projects/mcp-xp/venv/lib/python3.10/site-packages/anyio/_backends/_asyncio.py", line 772, in __aexit__
  |     raise BaseExceptionGroup(
  | exceptiongroup.ExceptionGroup: unhandled errors in a TaskGroup (1 sub-exception)
  +-+---------------- 1 ----------------
    | Traceback (most recent call last):
    |   File "/home/biniam/Desktop/Projects/mcp-xp/venv/lib/python3.10/site-packages/mcp/client/stdio/__init__.py", line 173, in stdio_client
    |     yield read_stream, write_stream
    | GeneratorExit
    | 
    | During handling of the above exception, another exception occurred:
    | 
    | Traceback (most recent call last):
    |   File "/home/biniam/Desktop/Projects/mcp-xp/venv/lib/python3.10/site-packages/mcp/client/stdio/__init__.py", line 179, in stdio_client
    |     process.terminate()
    |   File "/home/biniam/Desktop/Projects/mcp-xp/venv/lib/python3.10/site-packages/anyio/_backends/_asyncio.py", line 1085, in terminate
    |     self._process.terminate()
    |   File "/usr/lib/python3.10/asyncio/subprocess.py", line 140, in terminate
    |     self._transport.terminate()
    |   File "/usr/lib/python3.10/asyncio/base_subprocess.py", line 149, in terminate
    |     self._check_proc()
    |   File "/usr/lib/python3.10/asyncio/base_subprocess.py", line 142, in _check_proc
    |     raise ProcessLookupError()
    | ProcessLookupError
    +------------------------------------

During handling of the above exception, another exception occurred:

Traceback (most recent call last):
  File "/home/biniam/Desktop/Projects/mcp-xp/venv/lib/python3.10/site-packages/mcp/client/stdio/__init__.py", line 166, in stdio_client
    async with (
  File "/home/biniam/Desktop/Projects/mcp-xp/venv/lib/python3.10/site-packages/anyio/_backends/_asyncio.py", line 778, in __aexit__
    if self.cancel_scope.__exit__(type(exc), exc, exc.__traceback__):
  File "/home/biniam/Desktop/Projects/mcp-xp/venv/lib/python3.10/site-packages/anyio/_backends/_asyncio.py", line 457, in __exit__
    raise RuntimeError(
RuntimeError: Attempted to exit cancel scope in a different task than it was entered in
2025-03-30 17:42:13,402 - DEBUG - Using selector: EpollSelector
2025-03-30 17:42:13,403 - INFO - Starting chat session...
2025-03-30 17:42:13,773 - INFO - Server sqlite initialized successfully.
2025-03-30 17:42:15,397 - INFO - Server puppeteer initialized successfully.
2025-03-30 17:45:03,606 - ERROR - Error during cleanup of server sqlite: Attempted to exit cancel scope in a different task than it was entered in
2025-03-30 17:45:03,627 - ERROR - an error occurred during closing of asynchronous generator <async_generator object stdio_client at 0x711ac0781640>
asyncgen: <async_generator object stdio_client at 0x711ac0781640>
  + Exception Group Traceback (most recent call last):
  |   File "/home/biniam/Desktop/Projects/mcp-xp/venv/lib/python3.10/site-packages/anyio/_backends/_asyncio.py", line 772, in __aexit__
  |     raise BaseExceptionGroup(
  | exceptiongroup.ExceptionGroup: unhandled errors in a TaskGroup (1 sub-exception)
  +-+---------------- 1 ----------------
    | Traceback (most recent call last):
    |   File "/home/biniam/Desktop/Projects/mcp-xp/venv/lib/python3.10/site-packages/mcp/client/stdio/__init__.py", line 173, in stdio_client
    |     yield read_stream, write_stream
    | GeneratorExit
    | 
    | During handling of the above exception, another exception occurred:
    | 
    | Traceback (most recent call last):
    |   File "/home/biniam/Desktop/Projects/mcp-xp/venv/lib/python3.10/site-packages/mcp/client/stdio/__init__.py", line 179, in stdio_client
    |     process.terminate()
    |   File "/home/biniam/Desktop/Projects/mcp-xp/venv/lib/python3.10/site-packages/anyio/_backends/_asyncio.py", line 1085, in terminate
    |     self._process.terminate()
    |   File "/usr/lib/python3.10/asyncio/subprocess.py", line 140, in terminate
    |     self._transport.terminate()
    |   File "/usr/lib/python3.10/asyncio/base_subprocess.py", line 149, in terminate
    |     self._check_proc()
    |   File "/usr/lib/python3.10/asyncio/base_subprocess.py", line 142, in _check_proc
    |     raise ProcessLookupError()
    | ProcessLookupError
    +------------------------------------

During handling of the above exception, another exception occurred:

Traceback (most recent call last):
  File "/home/biniam/Desktop/Projects/mcp-xp/venv/lib/python3.10/site-packages/mcp/client/stdio/__init__.py", line 166, in stdio_client
    async with (
  File "/home/biniam/Desktop/Projects/mcp-xp/venv/lib/python3.10/site-packages/anyio/_backends/_asyncio.py", line 778, in __aexit__
    if self.cancel_scope.__exit__(type(exc), exc, exc.__traceback__):
  File "/home/biniam/Desktop/Projects/mcp-xp/venv/lib/python3.10/site-packages/anyio/_backends/_asyncio.py", line 457, in __exit__
    raise RuntimeError(
RuntimeError: Attempted to exit cancel scope in a different task than it was entered in
2025-03-30 17:45:03,629 - ERROR - an error occurred during closing of asynchronous generator <async_generator object stdio_client at 0x711ac0782e40>
asyncgen: <async_generator object stdio_client at 0x711ac0782e40>
  + Exception Group Traceback (most recent call last):
  |   File "/home/biniam/Desktop/Projects/mcp-xp/venv/lib/python3.10/site-packages/anyio/_backends/_asyncio.py", line 772, in __aexit__
  |     raise BaseExceptionGroup(
  | exceptiongroup.BaseExceptionGroup: unhandled errors in a TaskGroup (1 sub-exception)
  +-+---------------- 1 ----------------
    | Traceback (most recent call last):
    |   File "/home/biniam/Desktop/Projects/mcp-xp/venv/lib/python3.10/site-packages/mcp/client/stdio/__init__.py", line 173, in stdio_client
    |     yield read_stream, write_stream
    | GeneratorExit
    +------------------------------------

During handling of the above exception, another exception occurred:

Traceback (most recent call last):
  File "/home/biniam/Desktop/Projects/mcp-xp/venv/lib/python3.10/site-packages/mcp/client/stdio/__init__.py", line 166, in stdio_client
    async with (
  File "/home/biniam/Desktop/Projects/mcp-xp/venv/lib/python3.10/site-packages/anyio/_backends/_asyncio.py", line 778, in __aexit__
    if self.cancel_scope.__exit__(type(exc), exc, exc.__traceback__):
  File "/home/biniam/Desktop/Projects/mcp-xp/venv/lib/python3.10/site-packages/anyio/_backends/_asyncio.py", line 457, in __exit__
    raise RuntimeError(
RuntimeError: Attempted to exit cancel scope in a different task than it was entered in
2025-03-30 17:45:04,789 - DEBUG - Using selector: EpollSelector
2025-03-30 17:45:04,790 - INFO - Starting chat session...
2025-03-30 17:45:05,167 - INFO - Server sqlite initialized successfully.
2025-03-30 17:45:06,690 - INFO - Server puppeteer initialized successfully.
2025-03-30 17:45:23,427 - ERROR - an error occurred during closing of asynchronous generator <async_generator object stdio_client at 0x72b47cb92dc0>
asyncgen: <async_generator object stdio_client at 0x72b47cb92dc0>
  + Exception Group Traceback (most recent call last):
  |   File "/home/biniam/Desktop/Projects/mcp-xp/venv/lib/python3.10/site-packages/anyio/_backends/_asyncio.py", line 772, in __aexit__
  |     raise BaseExceptionGroup(
  | exceptiongroup.BaseExceptionGroup: unhandled errors in a TaskGroup (1 sub-exception)
  +-+---------------- 1 ----------------
    | Traceback (most recent call last):
    |   File "/home/biniam/Desktop/Projects/mcp-xp/venv/lib/python3.10/site-packages/mcp/client/stdio/__init__.py", line 173, in stdio_client
    |     yield read_stream, write_stream
    | GeneratorExit
    +------------------------------------

During handling of the above exception, another exception occurred:

Traceback (most recent call last):
  File "/home/biniam/Desktop/Projects/mcp-xp/venv/lib/python3.10/site-packages/mcp/client/stdio/__init__.py", line 166, in stdio_client
    async with (
  File "/home/biniam/Desktop/Projects/mcp-xp/venv/lib/python3.10/site-packages/anyio/_backends/_asyncio.py", line 778, in __aexit__
    if self.cancel_scope.__exit__(type(exc), exc, exc.__traceback__):
  File "/home/biniam/Desktop/Projects/mcp-xp/venv/lib/python3.10/site-packages/anyio/_backends/_asyncio.py", line 457, in __exit__
    raise RuntimeError(
RuntimeError: Attempted to exit cancel scope in a different task than it was entered in
2025-03-30 17:45:23,429 - ERROR - an error occurred during closing of asynchronous generator <async_generator object stdio_client at 0x72b47cfad740>
asyncgen: <async_generator object stdio_client at 0x72b47cfad740>
  + Exception Group Traceback (most recent call last):
  |   File "/home/biniam/Desktop/Projects/mcp-xp/venv/lib/python3.10/site-packages/anyio/_backends/_asyncio.py", line 772, in __aexit__
  |     raise BaseExceptionGroup(
  | exceptiongroup.BaseExceptionGroup: unhandled errors in a TaskGroup (1 sub-exception)
  +-+---------------- 1 ----------------
    | Traceback (most recent call last):
    |   File "/home/biniam/Desktop/Projects/mcp-xp/venv/lib/python3.10/site-packages/mcp/client/stdio/__init__.py", line 173, in stdio_client
    |     yield read_stream, write_stream
    | GeneratorExit
    +------------------------------------

During handling of the above exception, another exception occurred:

Traceback (most recent call last):
  File "/home/biniam/Desktop/Projects/mcp-xp/venv/lib/python3.10/site-packages/mcp/client/stdio/__init__.py", line 166, in stdio_client
    async with (
  File "/home/biniam/Desktop/Projects/mcp-xp/venv/lib/python3.10/site-packages/anyio/_backends/_asyncio.py", line 778, in __aexit__
    if self.cancel_scope.__exit__(type(exc), exc, exc.__traceback__):
  File "/home/biniam/Desktop/Projects/mcp-xp/venv/lib/python3.10/site-packages/anyio/_backends/_asyncio.py", line 457, in __exit__
    raise RuntimeError(
RuntimeError: Attempted to exit cancel scope in a different task than it was entered in
2025-03-30 17:45:23,429 - ERROR - an error occurred during closing of asynchronous generator <async_generator object stdio_client at 0x72b47cb915c0>
asyncgen: <async_generator object stdio_client at 0x72b47cb915c0>
  + Exception Group Traceback (most recent call last):
  |   File "/home/biniam/Desktop/Projects/mcp-xp/venv/lib/python3.10/site-packages/anyio/_backends/_asyncio.py", line 772, in __aexit__
  |     raise BaseExceptionGroup(
  | exceptiongroup.ExceptionGroup: unhandled errors in a TaskGroup (1 sub-exception)
  +-+---------------- 1 ----------------
    | Traceback (most recent call last):
    |   File "/home/biniam/Desktop/Projects/mcp-xp/venv/lib/python3.10/site-packages/mcp/client/stdio/__init__.py", line 173, in stdio_client
    |     yield read_stream, write_stream
    | GeneratorExit
    | 
    | During handling of the above exception, another exception occurred:
    | 
    | Traceback (most recent call last):
    |   File "/home/biniam/Desktop/Projects/mcp-xp/venv/lib/python3.10/site-packages/mcp/client/stdio/__init__.py", line 179, in stdio_client
    |     process.terminate()
    |   File "/home/biniam/Desktop/Projects/mcp-xp/venv/lib/python3.10/site-packages/anyio/_backends/_asyncio.py", line 1085, in terminate
    |     self._process.terminate()
    |   File "/usr/lib/python3.10/asyncio/subprocess.py", line 140, in terminate
    |     self._transport.terminate()
    |   File "/usr/lib/python3.10/asyncio/base_subprocess.py", line 149, in terminate
    |     self._check_proc()
    |   File "/usr/lib/python3.10/asyncio/base_subprocess.py", line 142, in _check_proc
    |     raise ProcessLookupError()
    | ProcessLookupError
    +------------------------------------

During handling of the above exception, another exception occurred:

Traceback (most recent call last):
  File "/home/biniam/Desktop/Projects/mcp-xp/venv/lib/python3.10/site-packages/mcp/client/stdio/__init__.py", line 166, in stdio_client
    async with (
  File "/home/biniam/Desktop/Projects/mcp-xp/venv/lib/python3.10/site-packages/anyio/_backends/_asyncio.py", line 778, in __aexit__
    if self.cancel_scope.__exit__(type(exc), exc, exc.__traceback__):
  File "/home/biniam/Desktop/Projects/mcp-xp/venv/lib/python3.10/site-packages/anyio/_backends/_asyncio.py", line 457, in __exit__
    raise RuntimeError(
RuntimeError: Attempted to exit cancel scope in a different task than it was entered in
2025-03-30 17:45:24,417 - DEBUG - Using selector: EpollSelector
2025-03-30 17:45:24,419 - INFO - Starting chat session...
2025-03-30 17:45:24,880 - INFO - Server sqlite initialized successfully.
2025-03-30 17:45:31,552 - INFO - Server puppeteer initialized successfully.
2025-03-30 17:47:18,935 - ERROR - Error during cleanup of server sqlite: Attempted to exit cancel scope in a different task than it was entered in
2025-03-30 17:47:18,957 - ERROR - an error occurred during closing of asynchronous generator <async_generator object stdio_client at 0x70abafe85640>
asyncgen: <async_generator object stdio_client at 0x70abafe85640>
  + Exception Group Traceback (most recent call last):
  |   File "/home/biniam/Desktop/Projects/mcp-xp/venv/lib/python3.10/site-packages/anyio/_backends/_asyncio.py", line 772, in __aexit__
  |     raise BaseExceptionGroup(
  | exceptiongroup.ExceptionGroup: unhandled errors in a TaskGroup (1 sub-exception)
  +-+---------------- 1 ----------------
    | Traceback (most recent call last):
    |   File "/home/biniam/Desktop/Projects/mcp-xp/venv/lib/python3.10/site-packages/mcp/client/stdio/__init__.py", line 173, in stdio_client
    |     yield read_stream, write_stream
    | GeneratorExit
    | 
    | During handling of the above exception, another exception occurred:
    | 
    | Traceback (most recent call last):
    |   File "/home/biniam/Desktop/Projects/mcp-xp/venv/lib/python3.10/site-packages/mcp/client/stdio/__init__.py", line 179, in stdio_client
    |     process.terminate()
    |   File "/home/biniam/Desktop/Projects/mcp-xp/venv/lib/python3.10/site-packages/anyio/_backends/_asyncio.py", line 1085, in terminate
    |     self._process.terminate()
    |   File "/usr/lib/python3.10/asyncio/subprocess.py", line 140, in terminate
    |     self._transport.terminate()
    |   File "/usr/lib/python3.10/asyncio/base_subprocess.py", line 149, in terminate
    |     self._check_proc()
    |   File "/usr/lib/python3.10/asyncio/base_subprocess.py", line 142, in _check_proc
    |     raise ProcessLookupError()
    | ProcessLookupError
    +------------------------------------

During handling of the above exception, another exception occurred:

Traceback (most recent call last):
  File "/home/biniam/Desktop/Projects/mcp-xp/venv/lib/python3.10/site-packages/mcp/client/stdio/__init__.py", line 166, in stdio_client
    async with (
  File "/home/biniam/Desktop/Projects/mcp-xp/venv/lib/python3.10/site-packages/anyio/_backends/_asyncio.py", line 778, in __aexit__
    if self.cancel_scope.__exit__(type(exc), exc, exc.__traceback__):
  File "/home/biniam/Desktop/Projects/mcp-xp/venv/lib/python3.10/site-packages/anyio/_backends/_asyncio.py", line 457, in __exit__
    raise RuntimeError(
RuntimeError: Attempted to exit cancel scope in a different task than it was entered in
2025-03-30 17:47:18,959 - ERROR - an error occurred during closing of asynchronous generator <async_generator object stdio_client at 0x70abafe86e40>
asyncgen: <async_generator object stdio_client at 0x70abafe86e40>
  + Exception Group Traceback (most recent call last):
  |   File "/home/biniam/Desktop/Projects/mcp-xp/venv/lib/python3.10/site-packages/anyio/_backends/_asyncio.py", line 772, in __aexit__
  |     raise BaseExceptionGroup(
  | exceptiongroup.BaseExceptionGroup: unhandled errors in a TaskGroup (1 sub-exception)
  +-+---------------- 1 ----------------
    | Traceback (most recent call last):
    |   File "/home/biniam/Desktop/Projects/mcp-xp/venv/lib/python3.10/site-packages/mcp/client/stdio/__init__.py", line 173, in stdio_client
    |     yield read_stream, write_stream
    | GeneratorExit
    +------------------------------------

During handling of the above exception, another exception occurred:

Traceback (most recent call last):
  File "/home/biniam/Desktop/Projects/mcp-xp/venv/lib/python3.10/site-packages/mcp/client/stdio/__init__.py", line 166, in stdio_client
    async with (
  File "/home/biniam/Desktop/Projects/mcp-xp/venv/lib/python3.10/site-packages/anyio/_backends/_asyncio.py", line 778, in __aexit__
    if self.cancel_scope.__exit__(type(exc), exc, exc.__traceback__):
  File "/home/biniam/Desktop/Projects/mcp-xp/venv/lib/python3.10/site-packages/anyio/_backends/_asyncio.py", line 457, in __exit__
    raise RuntimeError(
RuntimeError: Attempted to exit cancel scope in a different task than it was entered in
2025-03-30 17:47:20,469 - DEBUG - Using selector: EpollSelector
2025-03-30 17:47:20,470 - INFO - Starting chat session...
2025-03-30 17:47:20,851 - INFO - Server sqlite initialized successfully.
2025-03-30 17:47:22,387 - INFO - Server puppeteer initialized successfully.
2025-03-30 17:47:24,453 - ERROR - Error during cleanup of server sqlite: Attempted to exit cancel scope in a different task than it was entered in
2025-03-30 17:47:24,466 - ERROR - an error occurred during closing of asynchronous generator <async_generator object stdio_client at 0x7f5859e89640>
asyncgen: <async_generator object stdio_client at 0x7f5859e89640>
  + Exception Group Traceback (most recent call last):
  |   File "/home/biniam/Desktop/Projects/mcp-xp/venv/lib/python3.10/site-packages/anyio/_backends/_asyncio.py", line 772, in __aexit__
  |     raise BaseExceptionGroup(
  | exceptiongroup.ExceptionGroup: unhandled errors in a TaskGroup (1 sub-exception)
  +-+---------------- 1 ----------------
    | Traceback (most recent call last):
    |   File "/home/biniam/Desktop/Projects/mcp-xp/venv/lib/python3.10/site-packages/mcp/client/stdio/__init__.py", line 173, in stdio_client
    |     yield read_stream, write_stream
    | GeneratorExit
    | 
    | During handling of the above exception, another exception occurred:
    | 
    | Traceback (most recent call last):
    |   File "/home/biniam/Desktop/Projects/mcp-xp/venv/lib/python3.10/site-packages/mcp/client/stdio/__init__.py", line 179, in stdio_client
    |     process.terminate()
    |   File "/home/biniam/Desktop/Projects/mcp-xp/venv/lib/python3.10/site-packages/anyio/_backends/_asyncio.py", line 1085, in terminate
    |     self._process.terminate()
    |   File "/usr/lib/python3.10/asyncio/subprocess.py", line 140, in terminate
    |     self._transport.terminate()
    |   File "/usr/lib/python3.10/asyncio/base_subprocess.py", line 149, in terminate
    |     self._check_proc()
    |   File "/usr/lib/python3.10/asyncio/base_subprocess.py", line 142, in _check_proc
    |     raise ProcessLookupError()
    | ProcessLookupError
    +------------------------------------

During handling of the above exception, another exception occurred:

Traceback (most recent call last):
  File "/home/biniam/Desktop/Projects/mcp-xp/venv/lib/python3.10/site-packages/mcp/client/stdio/__init__.py", line 166, in stdio_client
    async with (
  File "/home/biniam/Desktop/Projects/mcp-xp/venv/lib/python3.10/site-packages/anyio/_backends/_asyncio.py", line 778, in __aexit__
    if self.cancel_scope.__exit__(type(exc), exc, exc.__traceback__):
  File "/home/biniam/Desktop/Projects/mcp-xp/venv/lib/python3.10/site-packages/anyio/_backends/_asyncio.py", line 457, in __exit__
    raise RuntimeError(
RuntimeError: Attempted to exit cancel scope in a different task than it was entered in
2025-03-30 17:47:24,467 - ERROR - an error occurred during closing of asynchronous generator <async_generator object stdio_client at 0x7f5859e8ae40>
asyncgen: <async_generator object stdio_client at 0x7f5859e8ae40>
  + Exception Group Traceback (most recent call last):
  |   File "/home/biniam/Desktop/Projects/mcp-xp/venv/lib/python3.10/site-packages/anyio/_backends/_asyncio.py", line 772, in __aexit__
  |     raise BaseExceptionGroup(
  | exceptiongroup.BaseExceptionGroup: unhandled errors in a TaskGroup (1 sub-exception)
  +-+---------------- 1 ----------------
    | Traceback (most recent call last):
    |   File "/home/biniam/Desktop/Projects/mcp-xp/venv/lib/python3.10/site-packages/mcp/client/stdio/__init__.py", line 173, in stdio_client
    |     yield read_stream, write_stream
    | GeneratorExit
    +------------------------------------

During handling of the above exception, another exception occurred:

Traceback (most recent call last):
  File "/home/biniam/Desktop/Projects/mcp-xp/venv/lib/python3.10/site-packages/mcp/client/stdio/__init__.py", line 166, in stdio_client
    async with (
  File "/home/biniam/Desktop/Projects/mcp-xp/venv/lib/python3.10/site-packages/anyio/_backends/_asyncio.py", line 778, in __aexit__
    if self.cancel_scope.__exit__(type(exc), exc, exc.__traceback__):
  File "/home/biniam/Desktop/Projects/mcp-xp/venv/lib/python3.10/site-packages/anyio/_backends/_asyncio.py", line 457, in __exit__
    raise RuntimeError(
RuntimeError: Attempted to exit cancel scope in a different task than it was entered in
2025-03-30 17:55:37,313 - DEBUG - Using selector: EpollSelector
2025-03-30 17:55:37,314 - INFO - Starting chat session...
2025-03-30 17:55:38,912 - INFO - Server sqlite initialized successfully.
2025-03-30 17:55:40,466 - INFO - Server puppeteer initialized successfully.
