2025-03-30 17:02:21,996 - DEBUG - Using selector: EpollSelector
2025-03-30 17:10:39,724 - ERROR - an error occurred during closing of asynchronous generator <async_generator object stdio_client at 0x7d7927a86840>
asyncgen: <async_generator object stdio_client at 0x7d7927a86840>
  + Exception Group Traceback (most recent call last):
  |   File "/home/biniam/Desktop/Projects/mcp-xp/venv/lib/python3.10/site-packages/anyio/_backends/_asyncio.py", line 772, in __aexit__
  |     raise BaseExceptionGroup(
  | exceptiongroup.ExceptionGroup: unhandled errors in a TaskGroup (1 sub-exception)
  +-+---------------- 1 ----------------
    | Traceback (most recent call last):
    |   File "/home/biniam/Desktop/Projects/mcp-xp/venv/lib/python3.10/site-packages/mcp/client/stdio/__init__.py", line 173, in stdio_client
    |     yield read_stream, write_stream
    | GeneratorExit
    | 
    | During handling of the above exception, another exception occurred:
    | 
    | Traceback (most recent call last):
    |   File "/home/biniam/Desktop/Projects/mcp-xp/venv/lib/python3.10/site-packages/mcp/client/stdio/__init__.py", line 179, in stdio_client
    |     process.terminate()
    |   File "/home/biniam/Desktop/Projects/mcp-xp/venv/lib/python3.10/site-packages/anyio/_backends/_asyncio.py", line 1085, in terminate
    |     self._process.terminate()
    |   File "/usr/lib/python3.10/asyncio/subprocess.py", line 140, in terminate
    |     self._transport.terminate()
    |   File "/usr/lib/python3.10/asyncio/base_subprocess.py", line 149, in terminate
    |     self._check_proc()
    |   File "/usr/lib/python3.10/asyncio/base_subprocess.py", line 142, in _check_proc
    |     raise ProcessLookupError()
    | ProcessLookupError
    +------------------------------------

During handling of the above exception, another exception occurred:

Traceback (most recent call last):
  File "/home/biniam/Desktop/Projects/mcp-xp/venv/lib/python3.10/site-packages/mcp/client/stdio/__init__.py", line 166, in stdio_client
    async with (
  File "/home/biniam/Desktop/Projects/mcp-xp/venv/lib/python3.10/site-packages/anyio/_backends/_asyncio.py", line 778, in __aexit__
    if self.cancel_scope.__exit__(type(exc), exc, exc.__traceback__):
  File "/home/biniam/Desktop/Projects/mcp-xp/venv/lib/python3.10/site-packages/anyio/_backends/_asyncio.py", line 457, in __exit__
    raise RuntimeError(
RuntimeError: Attempted to exit cancel scope in a different task than it was entered in
2025-03-30 17:10:39,726 - ERROR - an error occurred during closing of asynchronous generator <async_generator object stdio_client at 0x7d7927a85840>
asyncgen: <async_generator object stdio_client at 0x7d7927a85840>
  + Exception Group Traceback (most recent call last):
  |   File "/home/biniam/Desktop/Projects/mcp-xp/venv/lib/python3.10/site-packages/anyio/_backends/_asyncio.py", line 772, in __aexit__
  |     raise BaseExceptionGroup(
  | exceptiongroup.BaseExceptionGroup: unhandled errors in a TaskGroup (1 sub-exception)
  +-+---------------- 1 ----------------
    | Traceback (most recent call last):
    |   File "/home/biniam/Desktop/Projects/mcp-xp/venv/lib/python3.10/site-packages/mcp/client/stdio/__init__.py", line 173, in stdio_client
    |     yield read_stream, write_stream
    | GeneratorExit
    +------------------------------------

During handling of the above exception, another exception occurred:

Traceback (most recent call last):
  File "/home/biniam/Desktop/Projects/mcp-xp/venv/lib/python3.10/site-packages/mcp/client/stdio/__init__.py", line 166, in stdio_client
    async with (
  File "/home/biniam/Desktop/Projects/mcp-xp/venv/lib/python3.10/site-packages/anyio/_backends/_asyncio.py", line 778, in __aexit__
    if self.cancel_scope.__exit__(type(exc), exc, exc.__traceback__):
  File "/home/biniam/Desktop/Projects/mcp-xp/venv/lib/python3.10/site-packages/anyio/_backends/_asyncio.py", line 457, in __exit__
    raise RuntimeError(
RuntimeError: Attempted to exit cancel scope in a different task than it was entered in
2025-03-30 17:10:39,726 - ERROR - an error occurred during closing of asynchronous generator <async_generator object stdio_client at 0x7d7927a86f40>
asyncgen: <async_generator object stdio_client at 0x7d7927a86f40>
  + Exception Group Traceback (most recent call last):
  |   File "/home/biniam/Desktop/Projects/mcp-xp/venv/lib/python3.10/site-packages/anyio/_backends/_asyncio.py", line 772, in __aexit__
  |     raise BaseExceptionGroup(
  | exceptiongroup.BaseExceptionGroup: unhandled errors in a TaskGroup (1 sub-exception)
  +-+---------------- 1 ----------------
    | Traceback (most recent call last):
    |   File "/home/biniam/Desktop/Projects/mcp-xp/venv/lib/python3.10/site-packages/mcp/client/stdio/__init__.py", line 173, in stdio_client
    |     yield read_stream, write_stream
    | GeneratorExit
    +------------------------------------

During handling of the above exception, another exception occurred:

Traceback (most recent call last):
  File "/home/biniam/Desktop/Projects/mcp-xp/venv/lib/python3.10/site-packages/mcp/client/stdio/__init__.py", line 166, in stdio_client
    async with (
  File "/home/biniam/Desktop/Projects/mcp-xp/venv/lib/python3.10/site-packages/anyio/_backends/_asyncio.py", line 778, in __aexit__
    if self.cancel_scope.__exit__(type(exc), exc, exc.__traceback__):
  File "/home/biniam/Desktop/Projects/mcp-xp/venv/lib/python3.10/site-packages/anyio/_backends/_asyncio.py", line 457, in __exit__
    raise RuntimeError(
RuntimeError: Attempted to exit cancel scope in a different task than it was entered in
2025-03-30 17:10:41,539 - DEBUG - Using selector: EpollSelector
2025-03-30 17:10:41,540 - INFO - Starting chat session...
2025-03-30 17:10:41,919 - INFO - Server sqlite initialized successfully.
2025-03-30 17:10:44,017 - INFO - Server puppeteer initialized successfully.
2025-03-30 17:12:20,362 - ERROR - an error occurred during closing of asynchronous generator <async_generator object stdio_client at 0x71788468a740>
asyncgen: <async_generator object stdio_client at 0x71788468a740>
  + Exception Group Traceback (most recent call last):
  |   File "/home/biniam/Desktop/Projects/mcp-xp/venv/lib/python3.10/site-packages/anyio/_backends/_asyncio.py", line 772, in __aexit__
  |     raise BaseExceptionGroup(
  | exceptiongroup.ExceptionGroup: unhandled errors in a TaskGroup (1 sub-exception)
  +-+---------------- 1 ----------------
    | Traceback (most recent call last):
    |   File "/home/biniam/Desktop/Projects/mcp-xp/venv/lib/python3.10/site-packages/mcp/client/stdio/__init__.py", line 173, in stdio_client
    |     yield read_stream, write_stream
    | GeneratorExit
    | 
    | During handling of the above exception, another exception occurred:
    | 
    | Traceback (most recent call last):
    |   File "/home/biniam/Desktop/Projects/mcp-xp/venv/lib/python3.10/site-packages/mcp/client/stdio/__init__.py", line 179, in stdio_client
    |     process.terminate()
    |   File "/home/biniam/Desktop/Projects/mcp-xp/venv/lib/python3.10/site-packages/anyio/_backends/_asyncio.py", line 1085, in terminate
    |     self._process.terminate()
    |   File "/usr/lib/python3.10/asyncio/subprocess.py", line 140, in terminate
    |     self._transport.terminate()
    |   File "/usr/lib/python3.10/asyncio/base_subprocess.py", line 149, in terminate
    |     self._check_proc()
    |   File "/usr/lib/python3.10/asyncio/base_subprocess.py", line 142, in _check_proc
    |     raise ProcessLookupError()
    | ProcessLookupError
    +------------------------------------

During handling of the above exception, another exception occurred:

Traceback (most recent call last):
  File "/home/biniam/Desktop/Projects/mcp-xp/venv/lib/python3.10/site-packages/mcp/client/stdio/__init__.py", line 166, in stdio_client
    async with (
  File "/home/biniam/Desktop/Projects/mcp-xp/venv/lib/python3.10/site-packages/anyio/_backends/_asyncio.py", line 778, in __aexit__
    if self.cancel_scope.__exit__(type(exc), exc, exc.__traceback__):
  File "/home/biniam/Desktop/Projects/mcp-xp/venv/lib/python3.10/site-packages/anyio/_backends/_asyncio.py", line 457, in __exit__
    raise RuntimeError(
RuntimeError: Attempted to exit cancel scope in a different task than it was entered in
2025-03-30 17:12:20,366 - ERROR - an error occurred during closing of asynchronous generator <async_generator object stdio_client at 0x717884689740>
asyncgen: <async_generator object stdio_client at 0x717884689740>
  + Exception Group Traceback (most recent call last):
  |   File "/home/biniam/Desktop/Projects/mcp-xp/venv/lib/python3.10/site-packages/anyio/_backends/_asyncio.py", line 772, in __aexit__
  |     raise BaseExceptionGroup(
  | exceptiongroup.BaseExceptionGroup: unhandled errors in a TaskGroup (1 sub-exception)
  +-+---------------- 1 ----------------
    | Traceback (most recent call last):
    |   File "/home/biniam/Desktop/Projects/mcp-xp/venv/lib/python3.10/site-packages/mcp/client/stdio/__init__.py", line 173, in stdio_client
    |     yield read_stream, write_stream
    | GeneratorExit
    +------------------------------------

During handling of the above exception, another exception occurred:

Traceback (most recent call last):
  File "/home/biniam/Desktop/Projects/mcp-xp/venv/lib/python3.10/site-packages/mcp/client/stdio/__init__.py", line 166, in stdio_client
    async with (
  File "/home/biniam/Desktop/Projects/mcp-xp/venv/lib/python3.10/site-packages/anyio/_backends/_asyncio.py", line 778, in __aexit__
    if self.cancel_scope.__exit__(type(exc), exc, exc.__traceback__):
  File "/home/biniam/Desktop/Projects/mcp-xp/venv/lib/python3.10/site-packages/anyio/_backends/_asyncio.py", line 457, in __exit__
    raise RuntimeError(
RuntimeError: Attempted to exit cancel scope in a different task than it was entered in
2025-03-30 17:12:20,368 - ERROR - an error occurred during closing of asynchronous generator <async_generator object stdio_client at 0x71788468ae40>
asyncgen: <async_generator object stdio_client at 0x71788468ae40>
  + Exception Group Traceback (most recent call last):
  |   File "/home/biniam/Desktop/Projects/mcp-xp/venv/lib/python3.10/site-packages/anyio/_backends/_asyncio.py", line 772, in __aexit__
  |     raise BaseExceptionGroup(
  | exceptiongroup.BaseExceptionGroup: unhandled errors in a TaskGroup (1 sub-exception)
  +-+---------------- 1 ----------------
    | Traceback (most recent call last):
    |   File "/home/biniam/Desktop/Projects/mcp-xp/venv/lib/python3.10/site-packages/mcp/client/stdio/__init__.py", line 173, in stdio_client
    |     yield read_stream, write_stream
    | GeneratorExit
    +------------------------------------

During handling of the above exception, another exception occurred:

Traceback (most recent call last):
  File "/home/biniam/Desktop/Projects/mcp-xp/venv/lib/python3.10/site-packages/mcp/client/stdio/__init__.py", line 166, in stdio_client
    async with (
  File "/home/biniam/Desktop/Projects/mcp-xp/venv/lib/python3.10/site-packages/anyio/_backends/_asyncio.py", line 778, in __aexit__
    if self.cancel_scope.__exit__(type(exc), exc, exc.__traceback__):
  File "/home/biniam/Desktop/Projects/mcp-xp/venv/lib/python3.10/site-packages/anyio/_backends/_asyncio.py", line 457, in __exit__
    raise RuntimeError(
RuntimeError: Attempted to exit cancel scope in a different task than it was entered in
2025-03-30 17:14:34,785 - DEBUG - Using selector: EpollSelector
2025-03-30 17:14:34,786 - INFO - Starting chat session...
2025-03-30 17:14:35,911 - INFO - Server sqlite initialized successfully.
2025-03-30 17:14:37,455 - INFO - Server puppeteer initialized successfully.
2025-03-30 17:19:07,322 - ERROR - Error during cleanup of server sqlite: Attempted to exit cancel scope in a different task than it was entered in
2025-03-30 17:19:07,349 - ERROR - an error occurred during closing of asynchronous generator <async_generator object stdio_client at 0x7d5170981640>
asyncgen: <async_generator object stdio_client at 0x7d5170981640>
  + Exception Group Traceback (most recent call last):
  |   File "/home/biniam/Desktop/Projects/mcp-xp/venv/lib/python3.10/site-packages/anyio/_backends/_asyncio.py", line 772, in __aexit__
  |     raise BaseExceptionGroup(
  | exceptiongroup.ExceptionGroup: unhandled errors in a TaskGroup (1 sub-exception)
  +-+---------------- 1 ----------------
    | Traceback (most recent call last):
    |   File "/home/biniam/Desktop/Projects/mcp-xp/venv/lib/python3.10/site-packages/mcp/client/stdio/__init__.py", line 173, in stdio_client
    |     yield read_stream, write_stream
    | GeneratorExit
    | 
    | During handling of the above exception, another exception occurred:
    | 
    | Traceback (most recent call last):
    |   File "/home/biniam/Desktop/Projects/mcp-xp/venv/lib/python3.10/site-packages/mcp/client/stdio/__init__.py", line 179, in stdio_client
    |     process.terminate()
    |   File "/home/biniam/Desktop/Projects/mcp-xp/venv/lib/python3.10/site-packages/anyio/_backends/_asyncio.py", line 1085, in terminate
    |     self._process.terminate()
    |   File "/usr/lib/python3.10/asyncio/subprocess.py", line 140, in terminate
    |     self._transport.terminate()
    |   File "/usr/lib/python3.10/asyncio/base_subprocess.py", line 149, in terminate
    |     self._check_proc()
    |   File "/usr/lib/python3.10/asyncio/base_subprocess.py", line 142, in _check_proc
    |     raise ProcessLookupError()
    | ProcessLookupError
    +------------------------------------

During handling of the above exception, another exception occurred:

Traceback (most recent call last):
  File "/home/biniam/Desktop/Projects/mcp-xp/venv/lib/python3.10/site-packages/mcp/client/stdio/__init__.py", line 166, in stdio_client
    async with (
  File "/home/biniam/Desktop/Projects/mcp-xp/venv/lib/python3.10/site-packages/anyio/_backends/_asyncio.py", line 778, in __aexit__
    if self.cancel_scope.__exit__(type(exc), exc, exc.__traceback__):
  File "/home/biniam/Desktop/Projects/mcp-xp/venv/lib/python3.10/site-packages/anyio/_backends/_asyncio.py", line 457, in __exit__
    raise RuntimeError(
RuntimeError: Attempted to exit cancel scope in a different task than it was entered in
2025-03-30 17:19:07,352 - ERROR - an error occurred during closing of asynchronous generator <async_generator object stdio_client at 0x7d5170982e40>
asyncgen: <async_generator object stdio_client at 0x7d5170982e40>
  + Exception Group Traceback (most recent call last):
  |   File "/home/biniam/Desktop/Projects/mcp-xp/venv/lib/python3.10/site-packages/anyio/_backends/_asyncio.py", line 772, in __aexit__
  |     raise BaseExceptionGroup(
  | exceptiongroup.BaseExceptionGroup: unhandled errors in a TaskGroup (1 sub-exception)
  +-+---------------- 1 ----------------
    | Traceback (most recent call last):
    |   File "/home/biniam/Desktop/Projects/mcp-xp/venv/lib/python3.10/site-packages/mcp/client/stdio/__init__.py", line 173, in stdio_client
    |     yield read_stream, write_stream
    | GeneratorExit
    +------------------------------------

During handling of the above exception, another exception occurred:

Traceback (most recent call last):
  File "/home/biniam/Desktop/Projects/mcp-xp/venv/lib/python3.10/site-packages/mcp/client/stdio/__init__.py", line 166, in stdio_client
    async with (
  File "/home/biniam/Desktop/Projects/mcp-xp/venv/lib/python3.10/site-packages/anyio/_backends/_asyncio.py", line 778, in __aexit__
    if self.cancel_scope.__exit__(type(exc), exc, exc.__traceback__):
  File "/home/biniam/Desktop/Projects/mcp-xp/venv/lib/python3.10/site-packages/anyio/_backends/_asyncio.py", line 457, in __exit__
    raise RuntimeError(
RuntimeError: Attempted to exit cancel scope in a different task than it was entered in
2025-03-30 17:19:09,064 - DEBUG - Using selector: EpollSelector
2025-03-30 17:19:09,065 - INFO - Starting chat session...
2025-03-30 17:19:09,432 - INFO - Server sqlite initialized successfully.
2025-03-30 17:19:11,220 - INFO - Server puppeteer initialized successfully.
